<?xml version='1.0'?>
<sdf version='1.6'>
     <model name='tricycle_base'>

          <link name='base_link'>
               <pose frame=''>0 0 0 0 -0 0</pose>

               <inertial>
                    <pose frame=''>0 0 0.2 0 -0 0</pose>
                    <mass>10.001</mass>
                    <inertia>
                         <ixx>0.216767</ixx>
                         <ixy>0</ixy>
                         <ixz>0</ixz>
                         <iyy>0.216668</iyy>
                         <iyz>0</iyz>
                         <izz>0.416766</izz>
                    </inertia>
               </inertial>

               <visual name='base_link_fixed_joint_lump__chassis_visual_visual'>
                    <pose frame=''>0 0 0.2 0 -0 0</pose>
                    <geometry>
                         <box>
                              <size>0.5 0.5 0.1</size>
                         </box>
                    </geometry>
               </visual>

               <visual name='base_link_fixed_joint_lump__imu_link_visual_1'>
                    <pose frame=''>0 0 0.2 0 -0 0</pose>
                    <geometry>
                         <box>
                              <size>0.01 0.01 0.001</size>
                         </box>
                    </geometry>
               </visual>

               <collision name='base_link_fixed_joint_lump__chassis_collision'>
                    <pose frame=''>0 0 0.2 0 -0 0</pose>
                    <geometry>
                         <box>
                              <size>0.5 0.5 0.1</size>
                         </box>
                    </geometry>
               </collision>

               <collision name='base_link_fixed_joint_lump__imu_link_collision_1'>
                    <pose frame=''>0 0 0.2 0 -0 0</pose>
                    <geometry>
                         <box>
                              <size>0.01 0.01 0.001</size>
                         </box>
                    </geometry>
               </collision>
          </link>

          <link name='front_steering'>
               <pose frame=''>1 0 0.2 1.5708 -0 0</pose>
               <inertial>
                    <pose frame=''>0 0 0 0 -0 0</pose>
                    <mass>1</mass>
                    <inertia>
                         <ixx>0.000647258</ixx>
                         <ixy>0</ixy>
                         <ixz>0</ixz>
                         <iyy>0.000647258</iyy>
                         <iyz>0</iyz>
                         <izz>0.0003125</izz>
                    </inertia>
               </inertial>

               <visual name='front_steering_fixed_joint_lump__front_visual_visual'>
                    <pose frame=''>0 0 0 0 -0 0</pose>
                    <geometry>
                         <cylinder>
                              <length>0.07676</length>
                              <radius>0.025</radius>
                         </cylinder>
                    </geometry>
               </visual>
          </link>

          <link name='front_wheel'>
               <pose frame=''>1 0 0.2 1.5708 -0 0</pose>
               <gravity>1</gravity>

               <inertial>
                    <pose frame=''>0 0 0 0 -0 0</pose>
                    <mass>1</mass>
                    <inertia>
                         <ixx>0.0101227</ixx>
                         <ixy>0</ixy>
                         <ixz>0</ixz>
                         <iyy>0.0101227</iyy>
                         <iyz>0</iyz>
                         <izz>0.02</izz>
                    </inertia>
               </inertial>

               <visual name='front_wheel_visual_visual'>
                    <pose frame=''>0 0 0 0 -0 0</pose>
                    <geometry>
                         <cylinder>
                              <length>0.03838</length>
                              <radius>0.2</radius>
                         </cylinder>
                    </geometry>
               </visual>

               <collision name='front_wheel_collision'>
                    <pose frame=''>0 0 0 0 -0 0</pose>
                    <geometry>
                         <cylinder>
                              <radius>0.2</radius>
                              <length>0.03838</length>
                         </cylinder>
                    </geometry>
               </collision>
          </link>

          <link name='left_wheel'>
               <pose frame=''>-0 -0.375 0.2 -1.5708 -0 -0</pose>
               <inertial>
                    <pose frame=''>0 0 0 0 -0 0</pose>
                    <mass>1</mass>
                    <inertia>
                         <ixx>0.0101227</ixx>
                         <ixy>0</ixy>
                         <ixz>0</ixz>
                         <iyy>0.0101227</iyy>
                         <iyz>0</iyz>
                         <izz>0.02</izz>
                    </inertia>
               </inertial>

               <visual name='left_wheel_visual_visual'>
                    <pose frame=''>0 0 0 0 -0 0</pose>
                    <geometry>
                         <cylinder>
                              <length>0.03838</length>
                              <radius>0.2</radius>
                         </cylinder>
                    </geometry>
               </visual>

               <collision name='left_wheel_collision'>
                    <pose frame=''>0 0 0 0 -0 0</pose>
                    <geometry>
                         <cylinder>
                              <radius>0.2</radius>
                              <length>0.03838</length>
                         </cylinder>
                    </geometry>
               </collision>
          </link>

          <link name='right_wheel'>
               <pose frame=''>0 0.375 0.2 -1.5708 -0 -0</pose>

               <inertial>
                    <pose frame=''>0 0 0 0 -0 0</pose>
                    <mass>1</mass>
                    <inertia>
                         <ixx>0.0101227</ixx>
                         <ixy>0</ixy>
                         <ixz>0</ixz>
                         <iyy>0.0101227</iyy>
                         <iyz>0</iyz>
                         <izz>0.02</izz>
                    </inertia>
               </inertial>

               <visual name='right_wheel_visual_visual'>
                    <pose frame=''>0 0 0 0 -0 0</pose>
                    <geometry>
                         <cylinder>
                              <length>0.03838</length>
                              <radius>0.2</radius>
                         </cylinder>
                    </geometry>
               </visual>

               <collision name='right_wheel_collision'>
                    <pose frame=''>0 0 0 0 -0 0</pose>
                    <geometry>
                         <cylinder>
                              <radius>0.2</radius>
                              <length>0.03838</length>
                         </cylinder>
                    </geometry>

                    <surface>
                         <friction>
                              <ode>
                                   <mu>1</mu>
                                   <mu2>1</mu2>
                                   <fdir1>0 0 0</fdir1>
                                   <slip1>0</slip1>
                                   <slip2>0</slip2>
                              </ode>
                         </friction>
                    </surface>
               </collision>
          </link>

          <joint name='front_steering_joint' type='revolute'>
               <parent>base_link</parent>
               <child>front_steering</child>
               <pose frame=''>0 0 0 0 0 0</pose>
               <axis>
                    <xyz>0 0 1</xyz>
                    <use_parent_model_frame>1</use_parent_model_frame>
                    <limit>
                         <lower>-1.5708</lower>
                         <upper>1.5708</upper>
                         <effort>10</effort>
                         <velocity>10</velocity>
                    </limit>
               </axis>
          </joint>

          <joint name='front_wheel_joint' type='revolute'>
               <parent>front_steering</parent>
               <child>front_wheel</child>
               <pose frame=''>0 0 0 0 0 0</pose>
               <axis>
                    <xyz>0 1 0</xyz>
                    <use_parent_model_frame>1</use_parent_model_frame>
                    <limit>
                         <lower>-1e+16</lower>
                         <upper>1e+16</upper>
                         <effort>-1</effort>
                         <velocity>-1</velocity>
                    </limit>
               </axis>
          </joint>

          <joint name='left_wheel_joint' type='revolute'>
               <parent>base_link</parent>
               <child>left_wheel</child>
               <pose frame=''>0 0 0 0 -0 0</pose>
               <axis>
                    <xyz>0 1 0</xyz>
                    <use_parent_model_frame>1</use_parent_model_frame>
                    <limit>
                         <lower>-1e+16</lower>
                         <upper>1e+16</upper>
                         <effort>-1</effort>
                         <velocity>-1</velocity>
                    </limit>
               </axis>
          </joint>

          <joint name='right_wheel_joint' type='revolute'>
               <parent>base_link</parent>
               <child>right_wheel</child>
               <pose frame=''>0 0 0 0 -0 0</pose>
               <axis>
                    <xyz>0 1 0</xyz>
                    <use_parent_model_frame>1</use_parent_model_frame>
                    <limit>
                         <lower>-1e+16</lower>
                         <upper>1e+16</upper>
                         <effort>-1</effort>
                         <velocity>-1</velocity>
                    </limit>
               </axis>
          </joint>

          <plugin name='imu_controller' filename='libhector_gazebo_ros_imu.so'>
               <alwaysOn>true</alwaysOn>
               <topicName>tricycle/imu</topicName>
               <serviceName>imu/service</serviceName>
               <updateRate>50.0</updateRate>
               <gaussianNoise>0.005</gaussianNoise>
               <yawOffset>0.0</yawOffset>
               <yawDrift>0.02</yawDrift>
               <yawGaussianNoise>0.01</yawGaussianNoise>
               <rateOffset>0.0 0.0 0.0</rateOffset>
               <rateDrift>0.002 0.002 0.002</rateDrift>
               <rateGaussianNoise>0.001 0.001 0.001</rateGaussianNoise>
               <accelOffset>0.0 0.0 0.0</accelOffset>
               <accelDrift>0.005 0.005 0.005</accelDrift>
               <accelGaussianNoise>0.005 0.005 0.005</accelGaussianNoise>
               <robotNamespace>/</robotNamespace>
               <bodyName>base_link</bodyName>
               <xyzOffset>0 0 -0.2</xyzOffset>
               <rpyOffset>0 -0 0</rpyOffset>
          </plugin>

          <plugin name='tricycle_drive_controller' filename='libTricycleDriveModPlugin.so'>
               <rosDebugLevel>Debug</rosDebugLevel>
               <robotNamespace/>
               <publishWheelTF>true</publishWheelTF>
               <publishWheelJointState>true</publishWheelJointState>
               <alwaysOn>true</alwaysOn>
               <steeringJoint>front_steering_joint</steeringJoint>
               <actuatedWheelJoint>front_wheel_joint</actuatedWheelJoint>
               <encoderWheelLeftJoint>left_wheel_joint</encoderWheelLeftJoint>
               <encoderWheelRightJoint>right_wheel_joint</encoderWheelRightJoint>
               <actuatedWheelDiameter>0.2</actuatedWheelDiameter>
               <encoderWheelDiameter>0.2</encoderWheelDiameter>
               <encoderWheelSeparation>0.75</encoderWheelSeparation>
               <commandTopic>cmd_vel</commandTopic>
               <odometryTopic>odom</odometryTopic>
               <odometryFrame>odom</odometryFrame>
               <odometrySource>encoder</odometrySource>
               <robotBaseFrame>base_link</robotBaseFrame>
               <updateRate>50.0</updateRate>
               <wheelAcceleration>100.0</wheelAcceleration>
               <wheelDeceleration>100.0</wheelDeceleration>
               <wheelSpeedTolerance>0.05</wheelSpeedTolerance>
               <wheelTorque>5</wheelTorque>
               <steeringSpeed>1.5</steeringSpeed>
               <steeringAngleTolerance>0.03</steeringAngleTolerance>
               <steeringAngleLimit>1.5708</steeringAngleLimit>
          </plugin>


     </model>
</sdf>
